{
 "cells": [
  {
   "cell_type": "markdown",
   "metadata": {},
   "source": [
    "Ваш коллега прислал код функции:"
   ]
  },
  {
   "cell_type": "code",
   "execution_count": 16,
   "metadata": {},
   "outputs": [],
   "source": [
    "DEFAULT_USER_COUNT = 3\n",
    "\n",
    "def delete_and_return_last_user(region, default_list=['A100', 'A101', 'A102']):\n",
    "    \"\"\"\n",
    "    Удаляет из списка default_list последнего пользователя\n",
    "    и возвращает ID нового последнего пользователя.\n",
    "    \"\"\"\n",
    "    element_to_delete = default_list[-1]\n",
    "    default_list.remove(element_to_delete)\n",
    "\n",
    "    return default_list[DEFAULT_USER_COUNT-2]"
   ]
  },
  {
   "cell_type": "markdown",
   "metadata": {},
   "source": [
    "При однократном вызове этой функции все работает корректно:"
   ]
  },
  {
   "cell_type": "code",
   "execution_count": 17,
   "metadata": {},
   "outputs": [
    {
     "data": {
      "text/plain": [
       "'A101'"
      ]
     },
     "execution_count": 17,
     "metadata": {},
     "output_type": "execute_result"
    }
   ],
   "source": [
    "delete_and_return_last_user(1)"
   ]
  },
  {
   "cell_type": "markdown",
   "metadata": {},
   "source": [
    "Однако, при повторном вызове получается ошибка IndexError: list index out of range."
   ]
  },
  {
   "cell_type": "markdown",
   "metadata": {},
   "source": [
    "Задание:\n",
    "\n",
    "1. Что значит ошибка list index out of range?\n",
    "2. Почему при первом запуске функция работает корректно, а при втором - нет?"
   ]
  },
  {
   "cell_type": "markdown",
   "metadata": {},
   "source": [
    "list index out of range - означает что мы пытаемся получить доступ к элементу за пределами массива. В нашем случае - пытаемся запросить второй элемент в массиве из одного элемента."
   ]
  },
  {
   "cell_type": "markdown",
   "metadata": {},
   "source": [
    "Функция падает при втором вызове потому что в default_list при повторном вызове остается всего один элемент, а default_list[DEFAULT_USER_COUNT-2] обращается ко второму элементу и выходит за пределы массива. Логичнее использовать default_list[-1] в return и ловить ошибку когда список опустеет."
   ]
  }
 ],
 "metadata": {
  "kernelspec": {
   "display_name": "Python 3",
   "language": "python",
   "name": "python3"
  },
  "language_info": {
   "codemirror_mode": {
    "name": "ipython",
    "version": 3
   },
   "file_extension": ".py",
   "mimetype": "text/x-python",
   "name": "python",
   "nbconvert_exporter": "python",
   "pygments_lexer": "ipython3",
   "version": "3.8.0"
  }
 },
 "nbformat": 4,
 "nbformat_minor": 2
}
